Workbook

Sheet Tabelle1
A1: General data | G1: Sandwich | M1: Femtika | N1: Femtika settings | AD1: Washing | AG1: Drying | AJ1: Imaging | AO1: Sintering | AS1: OpenBIS
A2: Print # | B2: Code | C2: Print date | D2: Name | E2: Design | F2: 3DPoli path | G2: Resin | H2: Resin ID | I2: Substrate | J2: Substrate ID | K2: Spacer | M2: F path | N2: zmin | O2: zmax | P2: max z height [µm] | Q2: xmin | R2: xmax | S2: max x height [µm] | T2: ymin | U2: ymax | V2: max y height [µm] | W2: Lense | X2: R | Y2: Max power from calibration | Z2: Infinite FOV | AA2: Tilt alpha degree | AB2: Tilt beta degree | AC2: Tilt compensation | AD2: Washing date | AE2: Person | AF2: Washing solvent | AG2: CPD date | AH2: Person | AI2: CPD program | AJ2: SEM green state | AK2: SEM sintered | AL2: LiMi green state | AM2: LiMi sintered | AN2: Person | AO2: Sintering Date | AP2: Furnace | AQ2: Furnace ID | AR2: Profile Path | AS2: upload | AT2: uploaded | AU2: Comments
A3: =TEXT(C3,"jjjj")&TEXT(C3,"MM")&TEXT(C3,"tt")&"_"&"2PP_"&E3 -> 20260303_2PP_Text und BAM Logo | B3: 2PP-000001 | C3: 46084 | D3: alinden | E3: Text und BAM Logo | F3: \\GFS02\G42b\54LaufendePROJEKTE\PROJECTS\2025_VH5041_TransNanoAF\2PP\Experimente chronologisch\20260303_Array mit Text Logo und QR Code-fix2.txt | G3: 20260205 3YSZ 78w% | H3: =IFERROR(VLOOKUP(G3,Stammdaten!$I$2:$J$4,2,FALSE),"") -> 20260205131700798-40543 | I3: UV-Sheet 9 vom 03.02.2026 | J3: 20260203153656357-40208 | K3: 3 Tapes | W3: 63 x 1.4 | X3: 9000 | AD3: 46091 | AE3: alinden | AF3: Isopropanol | AG3: 46101 | AH3: alinden | AI3: 1 | AK3: 46126 | AL3: 46101 | AM3: 46121 | AN3: alinden | AO3: 46101 | AP3: LinnTherm 10 | AQ3: =IFERROR(VLOOKUP(AP3,Stammdaten!$U$2:$V$3,2,FALSE),"") -> 20251027120457399-19808 | AR3: "F:\PROJECTS\2025_VH5041_TransNanoAF\Digitalization\2PP in OpenBis\2PP_print protocol_20260213.xlsx"
A4: =TEXT(C4,"jjjj")&TEXT(C4,"MM")&TEXT(C4,"tt")&"_"&"2PP_"&E4 -> 20260303_2PP_Line distance cubes Cura vs 3D-Poli | B4: 2PP-000002 | C4: 46084 | D4: alinden | E4: Line distance cubes Cura vs 3D-Poli | F4: \\GFS02\G42b\54LaufendePROJEKTE\PROJECTS\2025_VH5041_TransNanoAF\2PP\Experimente chronologisch\20260303_array line distance 3Dpoli vs Cura.txt | G4: 20260205 3YSZ 78w% | H4: =IFERROR(VLOOKUP(G4,Stammdaten!$I$2:$J$4,2,FALSE),"") -> 20260205131700798-40543 | I4: UV-Sheet 9 vom 03.02.2026 | J4: 20260203153656357-40208 | K4: 3 Tapes | W4: 63 x 1.4 | X4: 9000 | AD4: 46091 | AE4: alinden | AF4: Isopropanol | AG4: 46101 | AH4: alinden | AI4: 1 | AK4: 46126 | AL4: 46101 | AM4: 46121 | AN4: alinden | AO4: 46101 | AP4: LinnTherm 10 | AQ4: =IFERROR(VLOOKUP(AP4,Stammdaten!$U$2:$V$3,2,FALSE),"") -> 20251027120457399-19808 | AR4: "F:\PROJECTS\2025_VH5041_TransNanoAF\Digitalization\2PP in OpenBis\2PP_print protocol_20260213.xlsx"
A5: =TEXT(C5,"jjjj")&TEXT(C5,"MM")&TEXT(C5,"tt")&"_"&"2PP_"&E5 -> 20260305_2PP_Multidirectional Slicing SchwarzP | B5: 2PP-000003 | C5: 46086 | D5: alinden | E5: Multidirectional Slicing SchwarzP | F5: \\GFS02\G42b\54LaufendePROJEKTE\PROJECTS\2025_VH5041_TransNanoAF\2PP\Experimente chronologisch\20260305_Array multidirectional slicing SchwarzP.txt | G5: 20260205 3YSZ 78w% | H5: =IFERROR(VLOOKUP(G5,Stammdaten!$I$2:$J$4,2,FALSE),"") -> 20260205131700798-40543 | I5: UV-Sheet 9 vom 03.02.2026 | J5: 20260203153656357-40208 | K5: 3 Tapes | W5: 63 x 1.4 | X5: 9000 | AD5: 46091 | AE5: alinden | AF5: Isopropanol | AG5: 46101 | AH5: alinden | AI5: 1 | AK5: 46126 | AL5: 46101 | AM5: 46121 | AN5: alinden | AO5: 46101 | AP5: LinnTherm 10 | AQ5: =IFERROR(VLOOKUP(AP5,Stammdaten!$U$2:$V$3,2,FALSE),"") -> 20251027120457399-19808 | AR5: "F:\PROJECTS\2025_VH5041_TransNanoAF\Digitalization\2PP in OpenBis\2PP_print protocol_20260213.xlsx"
A6: =TEXT(C6,"jjjj")&TEXT(C6,"MM")&TEXT(C6,"tt")&"_"&"2PP_"&E6 -> 20260305_2PP_Gradual Gratings | B6: 2PP-000004 | C6: 46086 | D6: alinden | E6: Gradual Gratings | F6: \\GFS02\G42b\54LaufendePROJEKTE\PROJECTS\2025_VH5041_TransNanoAF\2PP\Experimente chronologisch\20260305_Gradually Grating.txt | G6: 20260205 3YSZ 78w% | H6: =IFERROR(VLOOKUP(G6,Stammdaten!$I$2:$J$4,2,FALSE),"") -> 20260205131700798-40543 | I6: UV-Sheet 9 vom 03.02.2026 | J6: 20260203153656357-40208 | K6: 3 Tapes | W6: 63 x 1.4 | X6: 9000 | AD6: 46091 | AE6: alinden | AF6: Isopropanol | AG6: 46101 | AH6: alinden | AI6: 1 | AK6: 46126 | AL6: 46101 | AM6: 46121 | AN6: alinden | AO6: 46101 | AP6: LinnTherm 10 | AQ6: =IFERROR(VLOOKUP(AP6,Stammdaten!$U$2:$V$3,2,FALSE),"") -> 20251027120457399-19808 | AR6: "F:\PROJECTS\2025_VH5041_TransNanoAF\Digitalization\2PP in OpenBis\2PP_print protocol_20260213.xlsx"
A7: =TEXT(C7,"jjjj")&TEXT(C7,"MM")&TEXT(C7,"tt")&"_"&"2PP_"&E7 -> 20260309_2PP_2D dot matrix power x duration | B7: 2PP-000005 | C7: 46090 | D7: alinden | E7: 2D dot matrix power x duration | F7: \\GFS02\G42b\54LaufendePROJEKTE\PROJECTS\2025_VH5041_TransNanoAF\2PP\Experimente chronologisch\20260309_point matrix 2D power x duration.txt | G7: 20260205 3YSZ 78w% | H7: =IFERROR(VLOOKUP(G7,Stammdaten!$I$2:$J$4,2,FALSE),"") -> 20260205131700798-40543 | I7: UV-Sheet 1 vom 04.03.2026 | J7: 20260304152412162-47018 | K7: 3 Tapes | W7: 63 x 1.4 | X7: 9000 | AD7: 46094 | AE7: jmuelle4 | AF7: Isopropanol | AG7: 46101 | AH7: alinden | AI7: 1 | AK7: 46126 | AL7: 46101 | AM7: 46121 | AN7: alinden | AO7: 46101 | AP7: LinnTherm 10 | AQ7: =IFERROR(VLOOKUP(AP7,Stammdaten!$U$2:$V$3,2,FALSE),"") -> 20251027120457399-19808 | AR7: "F:\PROJECTS\2025_VH5041_TransNanoAF\Digitalization\2PP in OpenBis\2PP_print protocol_20260213.xlsx"
A8: =TEXT(C8,"jjjj")&TEXT(C8,"MM")&TEXT(C8,"tt")&"_"&"2PP_"&E8 -> 20260309_2PP_2D dot matrix power x duration_2 | B8: 2PP-000006 | C8: 46090 | D8: alinden | E8: 2D dot matrix power x duration_2 | F8: \\GFS02\G42b\54LaufendePROJEKTE\PROJECTS\2025_VH5041_TransNanoAF\2PP\Experimente chronologisch\20260309_point matrix 2D power x duration.txt | G8: 20260205 3YSZ 78w% | H8: =IFERROR(VLOOKUP(G8,Stammdaten!$I$2:$J$4,2,FALSE),"") -> 20260205131700798-40543 | I8: UV-Sheet 1 vom 04.03.2026 | J8: 20260304152412162-47018 | K8: 3 Tapes | W8: 63 x 1.4 | X8: 9000 | AD8: 46094 | AE8: jmuelle4 | AF8: Isopropanol | AG8: 46101 | AH8: alinden | AI8: 1 | AK8: 46126 | AL8: 46101 | AM8: 46121 | AN8: alinden | AO8: 46101 | AP8: LinnTherm 10 | AQ8: =IFERROR(VLOOKUP(AP8,Stammdaten!$U$2:$V$3,2,FALSE),"") -> 20251027120457399-19808 | AR8: "F:\PROJECTS\2025_VH5041_TransNanoAF\Digitalization\2PP in OpenBis\2PP_print protocol_20260213.xlsx"
A9: =TEXT(C9,"jjjj")&TEXT(C9,"MM")&TEXT(C9,"tt")&"_"&"2PP_"&E9 -> 20260310_2PP_Multidirectional Slicing SchwarzD | B9: 2PP-000007 | C9: 46091 | D9: alinden | E9: Multidirectional Slicing SchwarzD | F9: \\GFS02\G42b\54LaufendePROJEKTE\PROJECTS\2025_VH5041_TransNanoAF\2PP\Experimente chronologisch\20260309_Schwarz Diamond 3d-slicing.txt | G9: 20260205 3YSZ 78w% | H9: =IFERROR(VLOOKUP(G9,Stammdaten!$I$2:$J$4,2,FALSE),"") -> 20260205131700798-40543 | I9: UV-Sheet 1 vom 04.03.2026 | J9: 20260304152412162-47018 | K9: 3 Tapes | W9: 63 x 1.4 | X9: 9000 | AD9: 46094 | AE9: jmuelle4 | AF9: Isopropanol | AG9: 46101 | AH9: alinden | AI9: 1 | AK9: 46126 | AL9: 46101 | AM9: 46121 | AN9: alinden | AO9: 46101 | AP9: LinnTherm 10 | AQ9: =IFERROR(VLOOKUP(AP9,Stammdaten!$U$2:$V$3,2,FALSE),"") -> 20251027120457399-19808 | AR9: "F:\PROJECTS\2025_VH5041_TransNanoAF\Digitalization\2PP in OpenBis\2PP_print protocol_20260213.xlsx"
A10: =TEXT(C10,"jjjj")&TEXT(C10,"MM")&TEXT(C10,"tt")&"_"&"2PP_"&E10 -> 20260310_2PP_SchwarzP array 1-5 unit cells | B10: 2PP-000008 | C10: 46091 | D10: alinden | E10: SchwarzP array 1-5 unit cells | F10: \\GFS02\G42b\54LaufendePROJEKTE\PROJECTS\2025_VH5041_TransNanoAF\2PP\Experimente chronologisch\20260310_SchwarzP 1-5 unit cells array.txt | G10: 20260205 3YSZ 78w% | H10: =IFERROR(VLOOKUP(G10,Stammdaten!$I$2:$J$4,2,FALSE),"") -> 20260205131700798-40543 | I10: UV-Sheet 1 vom 04.03.2026 | J10: 20260304152412162-47018 | K10: 3 Tapes | P10: =O10-N10 -> 0 | S10: =R10-Q10 -> 0 | V10: =U10-T10 -> 0 | W10: 63 x 1.4 | X10: 9000 | AD10: 46094 | AE10: jmuelle4 | AF10: Isopropanol | AG10: 46101 | AH10: alinden | AI10: 1 | AK10: 46126 | AL10: 46101 | AM10: 46121 | AN10: alinden | AO10: 46101 | AP10: LinnTherm 10 | AQ10: =IFERROR(VLOOKUP(AP10,Stammdaten!$U$2:$V$3,2,FALSE),"") -> 20251027120457399-19808 | AR10: "F:\PROJECTS\2025_VH5041_TransNanoAF\Digitalization\2PP in OpenBis\2PP_print protocol_20260213.xlsx"
A11: =TEXT(C11,"jjjj")&TEXT(C11,"MM")&TEXT(C11,"tt")&"_"&"2PP_"&E11 -> 20260313_2PP_SP large infill test | B11: 2PP-000009 | C11: 46094 | D11: jmuelle4 | E11: SP large infill test | F11: \\GFS02\G42b\54LaufendePROJEKTE\PROJECTS\2025_VH5041_TransNanoAF\2PP\Experimente chronologisch\20260313_SP2x2x2_infill-line-distance_Array.txt | G11: 20260205 3YSZ 78w% | H11: =IFERROR(VLOOKUP(G11,Stammdaten!$I$2:$J$4,2,FALSE),"") -> 20260205131700798-40543 | I11: UV Sheet 2 vom 04.03.2026 | J11: 20260304152450862-47019 | K11: 3 Tapes | N11: 34640 | O11: 34821 | P11: =O11-N11 -> 181 | Q11: -17174 | R11: -10574 | S11: =R11-Q11 -> 6600 | T11: -6926 | U11: -10226 | V11: =U11-T11 -> -3300 | W11: 20 x 0.45 | X11: 9000 | Y11: 11.436 | Z11: On | AC11: On | AG11: 46101 | AH11: alinden | AI11: 1 | AQ11: =IFERROR(VLOOKUP(AP11,Stammdaten!$U$2:$V$3,2,FALSE),"") | AU11: 1x WMS --> Fehler in Skalierunge
A12: =TEXT(C12,"jjjj")&TEXT(C12,"MM")&TEXT(C12,"tt")&"_"&"2PP_"&E12 -> 20260316_2PP_SP large infill test | B12: 2PP-000010 | C12: 46097 | D12: jmuelle4 | E12: SP large infill test | F12: \\GFS02\G42b\54LaufendePROJEKTE\PROJECTS\2025_VH5041_TransNanoAF\2PP\Experimente chronologisch\20260313_SP2x2x2_infill-line-distance_Array.txt | G12: 20260205 3YSZ 78w% | H12: =IFERROR(VLOOKUP(G12,Stammdaten!$I$2:$J$4,2,FALSE),"") -> 20260205131700798-40543 | I12: UV Sheet 2 vom 04.03.2026 | J12: 20260304152450862-47019 | K12: 3 Tapes | N12: 34640 | O12: 34821 | P12: =O12-N12 -> 181 | Q12: -17174 | R12: -10574 | S12: =R12-Q12 -> 6600 | T12: -6926 | U12: -10226 | V12: =U12-T12 -> -3300 | W12: 20 x 0.45 | X12: 9000 | Y12: 11.486 | Z12: Off | AC12: On | AD12: 46100 | AE12: jmuelle4 | AF12: Isopropanol | AG12: 46101 | AH12: alinden | AI12: 1 | AK12: 46126 | AL12: 46101 | AM12: 46121 | AN12: alinden | AO12: 46101 | AP12: LinnTherm 10 | AQ12: =IFERROR(VLOOKUP(AP12,Stammdaten!$U$2:$V$3,2,FALSE),"") -> 20251027120457399-19808 | AR12: "F:\PROJECTS\2025_VH5041_TransNanoAF\Digitalization\2PP in OpenBis\2PP_print protocol_20260213.xlsx" | AU12: 2x WMS
A13: =TEXT(C13,"jjjj")&TEXT(C13,"MM")&TEXT(C13,"tt")&"_"&"2PP_"&E13 -> 20260316_2PP_Hybrid Pillar Array | B13: 2PP-000011 | C13: 46097 | D13: jmuelle4 | E13: Hybrid Pillar Array | F13: \\GFS02\G42b\54LaufendePROJEKTE\PROJECTS\2025_VH5041_TransNanoAF\2PP\Experimente chronologisch\20260316 Pillar Zylinder Array.txt | G13: 20250616 3YSZ in PEG-DA for 2PP-Kombi | H13: =IFERROR(VLOOKUP(G13,Stammdaten!$I$2:$J$4,2,FALSE),"") -> 20251209154344843-23579 | I13: Glas | K13: 2 Tapes | N13: 35090 | O13: 35207 | P13: =O13-N13 -> 117 | Q13: -64014 | R13: -19114 | S13: =R13-Q13 -> 44900 | T13: 2355 | U13: -8844 | V13: =U13-T13 -> -11199 | W13: 20 x 0.45 | X13: 9000 | Y13: 11.486 | Z13: Off | AC13: Off | AQ13: =IFERROR(VLOOKUP(AP13,Stammdaten!$U$2:$V$3,2,FALSE),"")
A14: =TEXT(C14,"jjjj")&TEXT(C14,"MM")&TEXT(C14,"tt")&"_"&"2PP_"&E14 -> 20260316_2PP_Hybrid Pillar Array &Mw | B14: 2PP-000012 | C14: 46097 | D14: jmuelle4 | E14: Hybrid Pillar Array &Mw | F14: \\GFS02\G42b\54LaufendePROJEKTE\PROJECTS\2025_VH5041_TransNanoAF\2PP\Experimente chronologisch\20260316 Pillar Zylinder Array 6mW.txt | G14: 20250616 3YSZ in PEG-DA for 2PP-Kombi | H14: =IFERROR(VLOOKUP(G14,Stammdaten!$I$2:$J$4,2,FALSE),"") -> 20251209154344843-23579 | I14: Glas | K14: 2 Tapes | N14: 35090 | O14: 35207 | P14: =O14-N14 -> 117 | Q14: -64014 | R14: -19114 | S14: =R14-Q14 -> 44900 | T14: 2355 | U14: -8844 | V14: =U14-T14 -> -11199 | W14: 20 x 0.45 | X14: 9000 | Y14: 11.486 | Z14: Off | AC14: Off | AQ14: =IFERROR(VLOOKUP(AP14,Stammdaten!$U$2:$V$3,2,FALSE),"")
A15: =TEXT(C15,"jjjj")&TEXT(C15,"MM")&TEXT(C15,"tt")&"_"&"2PP_"&E15 -> 20260317_2PP_Coordinate System Origin Test | B15: 2PP-000013 | C15: 46098 | D15: alinden | E15: Coordinate System Origin Test | F15: \\GFS02\G42b\54LaufendePROJEKTE\PROJECTS\2025_VH5041_TransNanoAF\2PP\Experimente chronologisch\20260317_Origin_Coordinate_System.txt | G15: 20260205 3YSZ 78w% | H15: =IFERROR(VLOOKUP(G15,Stammdaten!$I$2:$J$4,2,FALSE),"") -> 20260205131700798-40543 | I15: UV-Sheet 3 vom 04.03.2026 | J15: 20260304152609654-47020 | K15: 3 Tapes | N15: 59330 | O15: 59503 | P15: =O15-N15 -> 173 | Q15: -1518 | R15: -9719 | S15: =R15-Q15 -> -8201 | T15: 1176 | U15: -1523 | V15: =U15-T15 -> -2699 | W15: 63 x 1.4 | X15: 9000 | Y15: 11.735 | Z15: Off | AC15: Off | AD15: 46100 | AE15: jmuelle4 | AF15: Isopropanol | AG15: 46101 | AH15: alinden | AI15: 1 | AK15: 46126 | AL15: 46101 | AM15: 46121 | AN15: alinden | AO15: 46101 | AP15: LinnTherm 10 | AQ15: =IFERROR(VLOOKUP(AP15,Stammdaten!$U$2:$V$3,2,FALSE),"") -> 20251027120457399-19808 | AR15: "F:\PROJECTS\2025_VH5041_TransNanoAF\Digitalization\2PP in OpenBis\2PP_print protocol_20260213.xlsx"
A16: =TEXT(C16,"jjjj")&TEXT(C16,"MM")&TEXT(C16,"tt")&"_"&"2PP_"&E16 -> 20260317_2PP_UV-Sheet Text | B16: 2PP-000014 | C16: 46098 | D16: alinden | E16: UV-Sheet Text | F16: \\GFS02\G42b\54LaufendePROJEKTE\PROJECTS\2025_VH5041_TransNanoAF\2PP\Experimente chronologisch\20260317_New_UV-Sheet_Template.txt | G16: 20260205 3YSZ 78w% | H16: =IFERROR(VLOOKUP(G16,Stammdaten!$I$2:$J$4,2,FALSE),"") -> 20260205131700798-40543 | I16: UV-Sheet 3 vom 04.03.2026 | J16: 20260304152609654-47020 | K16: 3 Tapes | N16: 59330 | O16: 59503 | P16: =O16-N16 -> 173 | Q16: -1518 | R16: -9719 | S16: =R16-Q16 -> -8201 | T16: 1176 | U16: -1523 | V16: =U16-T16 -> -2699 | W16: 63 x 1.4 | X16: 9000 | Y16: 11.735 | Z16: Off | AC16: Off | AD16: 46100 | AE16: jmuelle4 | AF16: Isopropanol | AG16: 46101 | AH16: alinden | AI16: 1 | AK16: 46126 | AL16: 46101 | AM16: 46121 | AN16: alinden | AO16: 46101 | AP16: LinnTherm 10 | AQ16: =IFERROR(VLOOKUP(AP16,Stammdaten!$U$2:$V$3,2,FALSE),"") -> 20251027120457399-19808 | AR16: "F:\PROJECTS\2025_VH5041_TransNanoAF\Digitalization\2PP in OpenBis\2PP_print protocol_20260213.xlsx"
A17: =TEXT(C17,"jjjj")&TEXT(C17,"MM")&TEXT(C17,"tt")&"_"&"2PP_"&E17 -> 20260317_2PP_DataMatrix Code Test | B17: 2PP-000015 | C17: 46098 | D17: alinden | E17: DataMatrix Code Test | F17: \\GFS02\G42b\54LaufendePROJEKTE\PROJECTS\2025_VH5041_TransNanoAF\2PP\Experimente chronologisch\20260317_Data_Matrix_Code_Test.txt | G17: 20260205 3YSZ 78w% | H17: =IFERROR(VLOOKUP(G17,Stammdaten!$I$2:$J$4,2,FALSE),"") -> 20260205131700798-40543 | I17: UV-Sheet 3 vom 04.03.2026 | J17: 20260304152609654-47020 | K17: 3 Tapes | N17: 59330 | O17: 59503 | P17: =O17-N17 -> 173 | Q17: -1518 | R17: -9719 | S17: =R17-Q17 -> -8201 | T17: 1176 | U17: -1523 | V17: =U17-T17 -> -2699 | W17: 63 x 1.4 | X17: 9000 | Y17: 11.735 | Z17: Off | AC17: Off | AD17: 46100 | AE17: jmuelle4 | AF17: Isopropanol | AG17: 46101 | AH17: alinden | AI17: 1 | AK17: 46126 | AL17: 46101 | AM17: 46121 | AN17: alinden | AO17: 46101 | AP17: LinnTherm 10 | AQ17: =IFERROR(VLOOKUP(AP17,Stammdaten!$U$2:$V$3,2,FALSE),"") -> 20251027120457399-19808 | AR17: "F:\PROJECTS\2025_VH5041_TransNanoAF\Digitalization\2PP in OpenBis\2PP_print protocol_20260213.xlsx"
A18: =TEXT(C18,"jjjj")&TEXT(C18,"MM")&TEXT(C18,"tt")&"_"&"2PP_"&E18 -> 20260317_2PP_Pillars_TPMS | B18: 2PP-000016 | C18: 46098 | D18: alinden | E18: Pillars_TPMS | F18: \\GFS02\G42b\54LaufendePROJEKTE\PROJECTS\2025_VH5041_TransNanoAF\2PP\Experimente chronologisch\20260317_Pillars.txt | G18: 20260205 3YSZ 78w% | H18: =IFERROR(VLOOKUP(G18,Stammdaten!$I$2:$J$4,2,FALSE),"") -> 20260205131700798-40543 | I18: UV-Sheet 3 vom 04.03.2026 | J18: 20260304152609654-47020 | K18: 3 Tapes | N18: 59330 | O18: 59503 | P18: =O18-N18 -> 173 | Q18: -1518 | R18: -9719 | S18: =R18-Q18 -> -8201 | T18: 1176 | U18: -1523 | V18: =U18-T18 -> -2699 | W18: 63 x 1.4 | X18: 9000 | Y18: 11.735 | Z18: Off | AC18: On | AD18: 46100 | AE18: jmuelle4 | AF18: Isopropanol | AG18: 46101 | AH18: fblessma | AI18: 1 | AK18: 46126 | AL18: 46101 | AM18: 46121 | AN18: alinden | AO18: 46101 | AP18: LinnTherm 10 | AQ18: =IFERROR(VLOOKUP(AP18,Stammdaten!$U$2:$V$3,2,FALSE),"") -> 20251027120457399-19808 | AR18: "F:\PROJECTS\2025_VH5041_TransNanoAF\Digitalization\2PP in OpenBis\2PP_print protocol_20260213.xlsx"
A19: =TEXT(C19,"jjjj")&TEXT(C19,"MM")&TEXT(C19,"tt")&"_"&"2PP_"&E19 -> 20260319_2PP_Hybrid Pillar Array | B19: 2PP-000017 | C19: 46100 | D19: jmuelle4 | E19: Hybrid Pillar Array | F19: \\GFS02\G42b\54LaufendePROJEKTE\PROJECTS\2025_VH5041_TransNanoAF\2PP\Experimente chronologisch\20260319 Pillar Zylinder Array 6mW.txt | G19: 20250616 3YSZ in PEG-DA for 2PP-Kombi | H19: =IFERROR(VLOOKUP(G19,Stammdaten!$I$2:$J$4,2,FALSE),"") -> 20251209154344843-23579 | I19: Glas | K19: 2 Tapes. 2s UV | N19: 35060 | O19: 35211 | P19: =O19-N19 -> 151 | Q19: -16079 | R19: -9279 | S19: =R19-Q19 -> 6800 | T19: 4789 | U19: -1016 | V19: =U19-T19 -> -5805 | W19: 20 x 0.45 | X19: 9000 | Y19: 11.368 | Z19: Off | AC19: Off | AQ19: =IFERROR(VLOOKUP(AP19,Stammdaten!$U$2:$V$3,2,FALSE),"")
A20: =TEXT(C20,"jjjj")&TEXT(C20,"MM")&TEXT(C20,"tt")&"_"&"2PP_"&E20 -> 20260414_2PP_SchwarzP 2x2x2 array powerxspeed | B20: 2PP-000018 | C20: 46126 | D20: alinden | E20: SchwarzP 2x2x2 array powerxspeed | F20: \\GFS02\G42b\54LaufendePROJEKTE\PROJECTS\2025_VH5041_TransNanoAF\2PP\Experimente chronologisch\20260414_SchwarzP-hollow_2x2x2_power-speed-array.txt | G20: 20260205 3YSZ 78w% | H20: =IFERROR(VLOOKUP(G20,Stammdaten!$I$2:$J$5,2,FALSE),"") -> 20260205131700798-40543 | I20: UV-Sheet 4 vom 04.03.2026 | J20: 20260304152642775-47021 | K20: 3 Tapes | N20: 59517 | O20: 59670 | P20: =O20-N20 -> 153 | S20: =R20-Q20 -> 0 | V20: =U20-T20 -> 0 | W20: 63 x 1.4 | X20: 9000 | Y20: 11.701 | Z20: Off | AC20: On | AD20: 46135 | AE20: alinden | AF20: Isopropanol | AG20: 46135 | AH20: alinden | AI20: 1 | AK20: 46139 | AM20: 46139 | AN20: alinden | AO20: 46135 | AP20: LinnTherm 7 | AQ20: =IFERROR(VLOOKUP(AP20,Stammdaten!$U$2:$V$3,2,FALSE),"") -> 20251113141738982-20612 | AR20: "F:\PROJECTS\2025_VH5041_TransNanoAF\Digitalization\2PP in OpenBis\2PP_print protocol_20260213.xlsx"
A21: =TEXT(C21,"jjjj")&TEXT(C21,"MM")&TEXT(C21,"tt")&"_"&"2PP_"&E21 -> 20260415_2PP_SP large infill test | B21: 2PP-000019 | C21: 46127 | D21: jmuelle4 | E21: SP large infill test | F21: \\GFS02\G42b\54LaufendePROJEKTE\PROJECTS\2025_VH5041_TransNanoAF\2PP\Experimente chronologisch\20260415_SP2x2x2_infill-line-distance_Array.txt | G21: 20261107 3YSZ 78w% | H21: =IFERROR(VLOOKUP(G21,Stammdaten!$I$2:$J$5,2,FALSE),"") -> 20251113100232864-20580 | I21: UV-Sheet 5 vom 04.03.2026 | J21: 20260304152747687-47022 | K21: 3 Tapes | N21: 34620 | O21: 34721 | P21: =O21-N21 -> 101 | Q21: -15825 | R21: -10325 | S21: =R21-Q21 -> 5500 | T21: 3229 | U21: -70 | V21: =U21-T21 -> -3299 | W21: 20 x 0.45 | X21: 9000 | Y21: 11.458 | Z21: Off | AC21: Off | AD21: 46135 | AE21: alinden | AF21: Isopropanol | AG21: 46135 | AH21: alinden | AI21: 1 | AK21: 46139 | AM21: 46139 | AN21: alinden | AO21: 46135 | AP21: LinnTherm 7 | AQ21: =IFERROR(VLOOKUP(AP21,Stammdaten!$U$2:$V$3,2,FALSE),"") -> 20251113141738982-20612 | AR21: "F:\PROJECTS\2025_VH5041_TransNanoAF\Digitalization\2PP in OpenBis\2PP_print protocol_20260213.xlsx"
A22: =TEXT(C22,"jjjj")&TEXT(C22,"MM")&TEXT(C22,"tt")&"_"&"2PP_"&E22 -> 20260416_2PP_SP large infill test | B22: 2PP-000020 | C22: 46128 | D22: jmuelle4 | E22: SP large infill test | F22: \\GFS02\G42b\54LaufendePROJEKTE\PROJECTS\2025_VH5041_TransNanoAF\2PP\Experimente chronologisch\20260415_SP2x2x2_infill-line-distance_Array 2.txt | G22: 20261107 3YSZ 78w% | H22: =IFERROR(VLOOKUP(G22,Stammdaten!$I$2:$J$5,2,FALSE),"") -> 20251113100232864-20580 | I22: UV-Sheet 5 vom 04.03.2026 | J22: 20260304152747687-47022 | K22: 3 Tapes | N22: 34620 | O22: 34721 | P22: =O22-N22 -> 101 | Q22: -15825 | R22: -10325 | S22: =R22-Q22 -> 5500 | T22: 3229 | U22: -70 | V22: =U22-T22 -> -3299 | W22: 20 x 0.45 | X22: 9000 | Y22: 11.458 | Z22: Off | AC22: Off | AD22: 46135 | AE22: alinden | AF22: Isopropanol | AG22: 46135 | AH22: alinden | AI22: 1 | AK22: 46139 | AM22: 46139 | AN22: alinden | AO22: 46135 | AP22: LinnTherm 7 | AQ22: =IFERROR(VLOOKUP(AP22,Stammdaten!$U$2:$V$3,2,FALSE),"") -> 20251113141738982-20612 | AR22: "F:\PROJECTS\2025_VH5041_TransNanoAF\Digitalization\2PP in OpenBis\2PP_print protocol_20260213.xlsx"
A23: =TEXT(C23,"jjjj")&TEXT(C23,"MM")&TEXT(C23,"tt")&"_"&"2PP_"&E23 -> 20260416_2PP_DataMatrix Code Test2 | B23: 2PP-000021 | C23: 46128 | D23: alinden | E23: DataMatrix Code Test2 | F23: \\GFS02\G42b\54LaufendePROJEKTE\PROJECTS\2025_VH5041_TransNanoAF\2PP\Experimente chronologisch\20260416_Data_Matrix_Code_Test2.txt | G23: 20260205 3YSZ 78w% | H23: =IFERROR(VLOOKUP(G23,Stammdaten!$I$2:$J$5,2,FALSE),"") -> 20260205131700798-40543 | I23: UV-Sheet 4 vom 04.03.2026 | J23: 20260304152642775-47021 | K23: 3 Tapes | N23: 59490 | O23: 59678 | P23: =O23-N23 -> 188 | Q23: -13829 | R23: -10129 | S23: =R23-Q23 -> 3700 | T23: -3178 | U23: -178 | V23: =U23-T23 -> 3000 | W23: 63 x 1.4 | X23: 9000 | Y23: 11.707 | Z23: Off | AC23: Off | AD23: 46135 | AE23: alinden | AF23: Isopropanol | AG23: 46135 | AH23: alinden | AI23: 1 | AK23: 46139 | AM23: 46139 | AN23: alinden | AO23: 46135 | AP23: LinnTherm 7 | AQ23: =IFERROR(VLOOKUP(AP23,Stammdaten!$U$2:$V$3,2,FALSE),"") -> 20251113141738982-20612 | AR23: "F:\PROJECTS\2025_VH5041_TransNanoAF\Digitalization\2PP in OpenBis\2PP_print protocol_20260213.xlsx"
A24: =TEXT(C24,"jjjj")&TEXT(C24,"MM")&TEXT(C24,"tt")&"_"&"2PP_"&E24 -> 20260416_2PP_SchwarzP 2x2x2 array z-offsetxlayerheight | B24: 2PP-000022 | C24: 46128 | D24: alinden | E24: SchwarzP 2x2x2 array z-offsetxlayerheight | F24: \\GFS02\G42b\54LaufendePROJEKTE\PROJECTS\2025_VH5041_TransNanoAF\2PP\Experimente chronologisch\20260416_SchwarzP-hollow_2x2x2_zoffset-layerheight-array.txt | G24: 20260205 3YSZ 78w% | H24: =IFERROR(VLOOKUP(G24,Stammdaten!$I$2:$J$5,2,FALSE),"") -> 20260205131700798-40543 | I24: UV-Sheet 4 vom 04.03.2026 | J24: 20260304152642775-47021 | K24: 3 Tapes | N24: 59490 | O24: 59678 | P24: =O24-N24 -> 188 | Q24: -13829 | R24: -10129 | S24: =R24-Q24 -> 3700 | T24: -3178 | U24: -178 | V24: =U24-T24 -> 3000 | W24: 63 x 1.4 | X24: 9000 | Y24: 11.707 | Z24: Off | AC24: On | AD24: 46135 | AE24: alinden | AF24: Isopropanol | AG24: 46135 | AH24: alinden | AI24: 1 | AK24: 46139 | AM24: 46139 | AN24: alinden | AO24: 46135 | AP24: LinnTherm 7 | AQ24: =IFERROR(VLOOKUP(AP24,Stammdaten!$U$2:$V$3,2,FALSE),"") -> 20251113141738982-20612 | AR24: "F:\PROJECTS\2025_VH5041_TransNanoAF\Digitalization\2PP in OpenBis\2PP_print protocol_20260213.xlsx"
A25: =TEXT(C25,"jjjj")&TEXT(C25,"MM")&TEXT(C25,"tt")&"_"&"2PP_"&E25 -> 20260421_2PP_cubes 5x3 array | B25: 2PP-000023 | C25: 46133 | D25: alinden | E25: cubes 5x3 array | F25: \\GFS02\G42b\54LaufendePROJEKTE\PROJECTS\2025_VH5041_TransNanoAF\2PP\Experimente chronologisch\20260421_Cubes.txt | G25: 20260205 3YSZ 78w% | H25: =IFERROR(VLOOKUP(G25,Stammdaten!$I$2:$J$5,2,FALSE),"") -> 20260205131700798-40543 | I25: UV-Sheet_0005-1 | J25: 20260430131257526-50864 | K25: 3 Tapes | N25: 59610 | O25: 59812 | P25: =O25-N25 -> 202 | Q25: -16424 | R25: -11824 | S25: =R25-Q25 -> 4600 | T25: 1141 | U25: -2058 | V25: =U25-T25 -> -3199 | W25: 63 x 1.4 | X25: 9000 | Y25: 11.726 | Z25: Off | AC25: On | AD25: 46135 | AE25: alinden | AF25: Isopropanol | AG25: 46135 | AH25: alinden | AI25: 1 | AK25: 46139 | AM25: 46139 | AN25: alinden | AO25: 46135 | AP25: LinnTherm 7 | AQ25: =IFERROR(VLOOKUP(AP25,Stammdaten!$U$2:$V$3,2,FALSE),"") -> 20251113141738982-20612 | AR25: "F:\PROJECTS\2025_VH5041_TransNanoAF\Digitalization\2PP in OpenBis\2PP_print protocol_20260213.xlsx" | AU25: UV Sheet noch nicht in openBIS! -> nachtragen!
A26: =TEXT(C26,"jjjj")&TEXT(C26,"MM")&TEXT(C26,"tt")&"_"&"2PP_"&E26 -> 20260422_2PP_Schwarz P 2x2x2 array powerxspeed2 | B26: 2PP-000024 | C26: 46134 | D26: alinden | E26: Schwarz P 2x2x2 array powerxspeed2 | F26: \\GFS02\G42b\54LaufendePROJEKTE\PROJECTS\2025_VH5041_TransNanoAF\2PP\Experimente chronologisch\20260422_SchwarzP-hollow_2x2x2_power-speed-array.txt | G26: 20260205 3YSZ 78w% | H26: =IFERROR(VLOOKUP(G26,Stammdaten!$I$2:$J$5,2,FALSE),"") -> 20260205131700798-40543 | I26: UV-Sheet_0005-3 | J26: 20260430131303703-50866 | K26: 3 Tapes | N26: 59750 | O26: 59907 | P26: =O26-N26 -> 157 | Q26: -16547 | R26: -10447 | S26: =R26-Q26 -> 6100 | T26: -1139 | U26: -4439 | V26: =U26-T26 -> -3300 | W26: 63 x 1.4 | X26: 9000 | Y26: 11.667 | Z26: Off | AC26: Off | AD26: 46135 | AE26: alinden | AF26: Isopropanol | AG26: 46135 | AH26: alinden | AI26: 1 | AK26: 46139 | AM26: 46139 | AN26: alinden | AO26: 46135 | AP26: LinnTherm 7 | AQ26: =IFERROR(VLOOKUP(AP26,Stammdaten!$U$2:$V$3,2,FALSE),"") -> 20251113141738982-20612 | AR26: "F:\PROJECTS\2025_VH5041_TransNanoAF\Digitalization\2PP in OpenBis\2PP_print protocol_20260213.xlsx" | AU26: UV Sheet noch nicht in openBIS! -> nachtragen!
A27: =TEXT(C27,"jjjj")&TEXT(C27,"MM")&TEXT(C27,"tt")&"_"&"2PP_"&E27 -> 20260428_2PP_speed array 3x5 5mW 1000-10000 | B27: 2PP-000025 | C27: 46140 | D27: alinden | E27: speed array 3x5 5mW 1000-10000 | F27: \\GFS02\G42b\54LaufendePROJEKTE\PROJECTS\2025_VH5041_TransNanoAF\2PP\Experimente chronologisch\20260429_SchwarzP-hollow_2x2x2_5mW_speed-array.txt | G27: 20260205 3YSZ 78w% | H27: =IFERROR(VLOOKUP(G27,Stammdaten!$I$2:$J$5,2,FALSE),"") -> 20260205131700798-40543 | I27: UV-Sheet_0005-5 | J27: 20260430131310069-50868 | K27: 3 Tapes | N27: 59180 | O27: 59462 | P27: =O27-N27 -> 282 | Q27: -16631 | R27: -12831 | S27: =R27-Q27 -> 3800 | T27: 510 | U27: 2010 | V27: =U27-T27 -> 1500 | W27: 63 x 1.4 | X27: 9000 | Y27: 11.583 | Z27: Off | AC27: On | AD27: 46147 | AE27: alinden | AF27: Isopropanol | AG27: 46148 | AH27: alinden | AI27: 1 | AM27: 46168 | AN27: alinden | AO27: 46149 | AP27: LinnTherm 10 | AQ27: =IFERROR(VLOOKUP(AP27,Stammdaten!$U$2:$V$3,2,FALSE),"") -> 20251027120457399-19808 | AR27: "F:\PROJECTS\2025_VH5041_TransNanoAF\Digitalization\2PP in OpenBis\2PP_print protocol_20260213.xlsx"
A28: =TEXT(C28,"jjjj")&TEXT(C28,"MM")&TEXT(C28,"tt")&"_"&"2PP_"&E28 -> 20260428_2PP_speed array 3x5 8mW 7500-17500 | B28: 2PP-000026 | C28: 46140 | D28: alinden | E28: speed array 3x5 8mW 7500-17500 | F28: \\GFS02\G42b\54LaufendePROJEKTE\PROJECTS\2025_VH5041_TransNanoAF\2PP\Experimente chronologisch\20260429_SchwarzP-hollow_2x2x2_8mW_speed-array.txt | G28: 20260205 3YSZ 78w% | H28: =IFERROR(VLOOKUP(G28,Stammdaten!$I$2:$J$5,2,FALSE),"") -> 20260205131700798-40543 | I28: UV-Sheet_0005-5 | J28: 20260430131310069-50868 | K28: 3 Tapes | N28: 59180 | O28: 59462 | P28: =O28-N28 -> 282 | Q28: -16631 | R28: -12831 | S28: =R28-Q28 -> 3800 | T28: 510 | U28: 2010 | V28: =U28-T28 -> 1500 | W28: 63 x 1.4 | X28: 9000 | Y28: 11.583 | Z28: Off | AC28: On | AD28: 46147 | AE28: alinden | AF28: Isopropanol | AG28: 46148 | AH28: alinden | AI28: 1 | AM28: 46168 | AN28: alinden | AO28: 46149 | AP28: LinnTherm 10 | AQ28: =IFERROR(VLOOKUP(AP28,Stammdaten!$U$2:$V$3,2,FALSE),"") -> 20251027120457399-19808 | AR28: "F:\PROJECTS\2025_VH5041_TransNanoAF\Digitalization\2PP in OpenBis\2PP_print protocol_20260213.xlsx"
A29: =TEXT(C29,"jjjj")&TEXT(C29,"MM")&TEXT(C29,"tt")&"_"&"2PP_"&E29 -> 20260504_2PP_cubes 3x3 array 7,8,9mW | B29: 2PP-000027 | C29: 46146 | D29: alinden | E29: cubes 3x3 array 7,8,9mW | F29: \\GFS02\G42b\54LaufendePROJEKTE\PROJECTS\2025_VH5041_TransNanoAF\2PP\Experimente chronologisch\20260504_cubes-dense_8mW_3x3.txt | G29: 20260205 3YSZ 78w% | H29: =IFERROR(VLOOKUP(G29,Stammdaten!$I$2:$J$5,2,FALSE),"") -> 20260205131700798-40543 | I29: UV-Sheet_0007-1 | J29: 20260609094438586-53109 | K29: 3 Tapes | N29: 59360 | O29: 59541 | P29: =O29-N29 -> 181 | Q29: -12867 | R29: -8767 | S29: =R29-Q29 -> 4100 | T29: -689 | U29: 1410 | V29: =U29-T29 -> 2099 | W29: 63 x 1.4 | X29: 9000 | Y29: 11.792 | Z29: Off | AC29: Off | AD29: 46147 | AE29: alinden | AF29: Isopropanol | AG29: 46148 | AH29: alinden | AI29: 1 | AM29: 46168 | AN29: alinden | AO29: 46149 | AP29: LinnTherm 10 | AQ29: =IFERROR(VLOOKUP(AP29,Stammdaten!$U$2:$V$3,2,FALSE),"") -> 20251027120457399-19808 | AR29: "F:\PROJECTS\2025_VH5041_TransNanoAF\Digitalization\2PP in OpenBis\2PP_print protocol_20260213.xlsx"
A30: =TEXT(C30,"jjjj")&TEXT(C30,"MM")&TEXT(C30,"tt")&"_"&"2PP_"&E30 -> 20260504_2PP_cubes 3x3 array 4,5,6mW | B30: 2PP-000028 | C30: 46146 | D30: alinden | E30: cubes 3x3 array 4,5,6mW | F30: \\GFS02\G42b\54LaufendePROJEKTE\PROJECTS\2025_VH5041_TransNanoAF\2PP\Experimente chronologisch\20260504_cubes-dense_5mW_3x3.txt | G30: 20260205 3YSZ 78w% | H30: =IFERROR(VLOOKUP(G30,Stammdaten!$I$2:$J$5,2,FALSE),"") -> 20260205131700798-40543 | I30: UV-Sheet_0007-1 | J30: 20260609094438586-53109 | K30: 3 Tapes | N30: 59360 | O30: 59541 | P30: =O30-N30 -> 181 | Q30: -12867 | R30: -8767 | S30: =R30-Q30 -> 4100 | T30: -689 | U30: 1410 | V30: =U30-T30 -> 2099 | W30: 63 x 1.4 | X30: 9000 | Y30: 11.792 | Z30: Off | AC30: Off | AD30: 46147 | AE30: alinden | AF30: Isopropanol | AG30: 46148 | AH30: alinden | AI30: 1 | AM30: 46168 | AN30: alinden | AO30: 46149 | AP30: LinnTherm 10 | AQ30: =IFERROR(VLOOKUP(AP30,Stammdaten!$U$2:$V$3,2,FALSE),"") -> 20251027120457399-19808 | AR30: "F:\PROJECTS\2025_VH5041_TransNanoAF\Digitalization\2PP in OpenBis\2PP_print protocol_20260213.xlsx"
A31: =TEXT(C31,"jjjj")&TEXT(C31,"MM")&TEXT(C31,"tt")&"_"&"2PP_"&E31 -> 20260505_2PP_cubes u Schwarz P array nanoindent(8mW) | B31: 2PP-000029 | C31: 46147 | D31: alinden | E31: cubes u Schwarz P array nanoindent(8mW) | F31: \\GFS02\G42b\54LaufendePROJEKTE\PROJECTS\2025_VH5041_TransNanoAF\2PP\Experimente chronologisch\20260505_cubes-schwarzP-array-nanoindent_8mW.txt | G31: 20260205 3YSZ 78w% | H31: =IFERROR(VLOOKUP(G31,Stammdaten!$I$2:$J$5,2,FALSE),"") -> 20260205131700798-40543 | I31: UV-Sheet_0007-1 | J31: 20260609094438586-53109 | K31: 3 Tapes | N31: 59360 | O31: 59541 | P31: =O31-N31 -> 181 | Q31: -12867 | R31: -8767 | S31: =R31-Q31 -> 4100 | T31: -689 | U31: 1410 | V31: =U31-T31 -> 2099 | W31: 63 x 1.4 | X31: 9000 | Y31: 11.792 | Z31: Off | AC31: On | AD31: 46147 | AE31: alinden | AF31: Isopropanol | AG31: 46148 | AH31: alinden | AI31: 1 | AM31: 46168 | AN31: alinden | AO31: 46149 | AP31: LinnTherm 10 | AQ31: =IFERROR(VLOOKUP(AP31,Stammdaten!$U$2:$V$3,2,FALSE),"") -> 20251027120457399-19808 | AR31: "F:\PROJECTS\2025_VH5041_TransNanoAF\Digitalization\2PP in OpenBis\2PP_print protocol_20260213.xlsx"
A32: =TEXT(C32,"jjjj")&TEXT(C32,"MM")&TEXT(C32,"tt")&"_"&"2PP_"&E32 -> 20260505_2PP_cubes u Schwarz P array nanoindent(5mW) | B32: 2PP-000030 | C32: 46147 | D32: alinden | E32: cubes u Schwarz P array nanoindent(5mW) | F32: \\GFS02\G42b\54LaufendePROJEKTE\PROJECTS\2025_VH5041_TransNanoAF\2PP\Experimente chronologisch\20260505_cubes-schwarzP-array-nanoindent_5mW.txt | G32: 20260205 3YSZ 78w% | H32: =IFERROR(VLOOKUP(G32,Stammdaten!$I$2:$J$5,2,FALSE),"") -> 20260205131700798-40543 | I32: UV-Sheet_0007-1 | J32: 20260609094438586-53109 | K32: 3 Tapes | N32: 59360 | O32: 59541 | P32: =O32-N32 -> 181 | Q32: -12867 | R32: -8767 | S32: =R32-Q32 -> 4100 | T32: -689 | U32: 1410 | V32: =U32-T32 -> 2099 | W32: 63 x 1.4 | X32: 9000 | Y32: 11.792 | Z32: Off | AC32: On | AD32: 46147 | AE32: alinden | AF32: Isopropanol | AG32: 46148 | AH32: alinden | AI32: 1 | AM32: 46168 | AN32: alinden | AO32: 46149 | AP32: LinnTherm 10 | AQ32: =IFERROR(VLOOKUP(AP32,Stammdaten!$U$2:$V$3,2,FALSE),"") -> 20251027120457399-19808 | AR32: "F:\PROJECTS\2025_VH5041_TransNanoAF\Digitalization\2PP in OpenBis\2PP_print protocol_20260213.xlsx"
A33: =TEXT(C33,"jjjj")&TEXT(C33,"MM")&TEXT(C33,"tt")&"_"&"2PP_"&E33 -> 20260529_2PP_cubes 3x3 array 4,5,6mW | B33: 2PP-000031 | C33: 46171 | D33: alinden | E33: cubes 3x3 array 4,5,6mW | G33: 20260205 3YSZ 78w% | H33: =IFERROR(VLOOKUP(G33,Stammdaten!$I$2:$J$5,2,FALSE),"") -> 20260205131700798-40543 | I33: UV-Sheet_0005-2 | J33: 20260430131253315-50863 | K33: 3 Tapes | N33: 59490 | O33: 59653 | P33: =O33-N33 -> 163 | S33: =R33-Q33 -> 0 | V33: =U33-T33 -> 0 | W33: 63 x 1.4 | X33: 9000 | Y33: 12.046 | Z33: Off | AC33: On | AD33: 46174 | AE33: fblessma | AF33: Isopropanol | AG33: 46185 | AH33: alinden | AI33: 1 | AQ33: =IFERROR(VLOOKUP(AP33,Stammdaten!$U$2:$V$3,2,FALSE),"")
A34: =TEXT(C34,"jjjj")&TEXT(C34,"MM")&TEXT(C34,"tt")&"_"&"2PP_"&E34 -> 20260601_2PP_Pillar Test 8YSZ | B34: 2PP-000032 | C34: 46174 | D34: fblessma | E34: Pillar Test 8YSZ | G34: 20260528 8YSZ 78wt% | H34: 20260528144122603-52269 | I34: 20260126 UV Sheet 2 | J34: 20260126175936336-39132 | K34: 3 Tapes | P34: =O34-N34 -> 0 | S34: =R34-Q34 -> 0 | V34: =U34-T34 -> 0 | AD34: 46174 | AE34: fblessma | AF34: Isopropanol | AG34: 46185 | AH34: alinden | AI34: 1 | AQ34: =IFERROR(VLOOKUP(AP34,Stammdaten!$U$2:$V$3,2,FALSE),"")
A35: =TEXT(C35,"jjjj")&TEXT(C35,"MM")&TEXT(C35,"tt")&"_"&"2PP_"&E35 -> 19000100_2PP_ | B35: 2PP-000033 | H35: =IFERROR(VLOOKUP(#REF!,Stammdaten!$I$2:$J$5,2,FALSE),"") | P35: =O35-N35 -> 0 | S35: =R35-Q35 -> 0 | V35: =U35-T35 -> 0 | AQ35: =IFERROR(VLOOKUP(AP35,Stammdaten!$U$2:$V$3,2,FALSE),"")
A36: =TEXT(C36,"jjjj")&TEXT(C36,"MM")&TEXT(C36,"tt")&"_"&"2PP_"&E36 -> 19000100_2PP_ | B36: 2PP-000034 | H36: =IFERROR(VLOOKUP(G35,Stammdaten!$I$2:$J$5,2,FALSE),"") | P36: =O36-N36 -> 0 | S36: =R36-Q36 -> 0 | V36: =U36-T36 -> 0 | AQ36: =IFERROR(VLOOKUP(AP36,Stammdaten!$U$2:$V$3,2,FALSE),"")
A37: =TEXT(C37,"jjjj")&TEXT(C37,"MM")&TEXT(C37,"tt")&"_"&"2PP_"&E37 -> 20260602_2PP_Bussi 100µm 1000 6mW | B37: 2PP-000035 | C37: 46175 | D37: jmuelle4 | E37: Bussi 100µm 1000 6mW | G37: 20260205 3YSZ 78w% | H37: =IFERROR(VLOOKUP(G37,Stammdaten!$I$2:$J$5,2,FALSE),"") -> 20260205131700798-40543 | I37: UV-Sheet_0008-1 | J37: 20260609094439480-53111 | K37: 3 Tapes | N37: 59740 | O37: 59911 | P37: =O37-N37 -> 171 | Q37: -8334 | R37: -17134 | S37: =R37-Q37 -> -8800 | T37: 1283 | U37: -3016 | V37: =U37-T37 -> -4299 | W37: 63 x 1.4 | X37: 9000 | Y37: 12.311 | Z37: On | AC37: Off | AQ37: =IFERROR(VLOOKUP(AP37,Stammdaten!$U$2:$V$3,2,FALSE),"")
A38: =TEXT(C38,"jjjj")&TEXT(C38,"MM")&TEXT(C38,"tt")&"_"&"2PP_"&E38 -> 20260602_2PP_Bussi 100µm 5000 4mW | B38: 2PP-000036 | C38: 46175 | D38: jmuelle4 | E38: Bussi 100µm 5000 4mW | G38: 20260205 3YSZ 78w% | H38: =IFERROR(VLOOKUP(G38,Stammdaten!$I$2:$J$5,2,FALSE),"") -> 20260205131700798-40543 | I38: UV-Sheet_0008-1 | J38: 20260609094439480-53111 | K38: 3 Tapes | N38: 59740 | O38: 59911 | P38: =O38-N38 -> 171 | Q38: -8334 | R38: -17134 | S38: =R38-Q38 -> -8800 | T38: 1283 | U38: -3016 | V38: =U38-T38 -> -4299 | W38: 63 x 1.4 | X38: 9000 | Y38: 12.311 | Z38: On | AC38: Off | AQ38: =IFERROR(VLOOKUP(AP38,Stammdaten!$U$2:$V$3,2,FALSE),"")
A39: =TEXT(C39,"jjjj")&TEXT(C39,"MM")&TEXT(C39,"tt")&"_"&"2PP_"&E39 -> 19000100_2PP_ | B39: 2PP-000037 | D39: jmuelle4
A40: =TEXT(C40,"jjjj")&TEXT(C40,"MM")&TEXT(C40,"tt")&"_"&"2PP_"&E40 -> 19000100_2PP_ | B40: 2PP-000038 | D40: jmuelle4
...

Sheet Stammdaten
A1: Print # | B1: Print date | C1: Name | D1: Print object | E1: Lense | F1: z0 | G1: zmax | H1: max z height [µm] | I1: Resin | J1: Resin ID | K1: Substrate | L1: Substrate ID | M1: Infinite FOV | N1: Tilt compensation | O1: Washing date | P1: Washing solvent | Q1: CPD date | R1: CPD settings | S1: SEM green state | T1: SEM sintered | U1: Furnace | V1: Furnace ID | W1: OpenBIS
C2: Name | E2: 63 x 1.4 | I2: 20260205 3YSZ 78w% | J2: 20260205131700798-40543 | M2: On | N2: On | P2: Isopropanol | U2: LinnTherm 7 | V2: 20251113141738982-20612 | W2: Yes
C3: jmuelle4 | E3: 20 x 0.45 | I3: 20260126 8YSZ 75w% | J3: 20260126125322691-38571 | M3: Off | N3: Off | U3: LinnTherm 10 | V3: 20251027120457399-19808 | W3: No
C4: alinden | I4: 20250616 3YSZ in PEG-DA for 2PP-Kombi | J4: 20251209154344843-23579
C5: fblessma | I5: 20261107 3YSZ 78w% | J5: 20251113100232864-20580
C6: ejanoth
C7: swiedeha
C8: fblessma | I8: 20260528 8YSZ 78wt% | J8: 20260528144122603-52269
